Workbook

Sheet Lath
A1: Name | B1: Kgs/ m2 | C1: Lath weight / m length | D1: Compressed lath height | E1: uncompressed lath height | F1: attachment strap | G1: Thickness | H1: Friction % | I1: max width | J1: min axle diameter | K1: max m2 | L1: vision percentage | M1: Lath image | N1: Wind | O1: Material | P1: Insulation value | Q1: Product group | R1: Wicket available | S1: Lath type | T1: reversible | U1: Motor usage type available
A2: 75mm 22swg, Solid 9.3kg/sqm | B2: 9.3 | D2: 73 | E2: 80 | F2: 73 | G2: 17 | H2: 10 | I2: 4600 | J2: 100 | L2: 0 | N2: no | O2: Steel | P2: none | Q2: Securodoor | R2: Yes | S2: 75mm lath | T2: Yes | U2: Standard, Hi usage, Hi speed(warning)
A3: 75mm Wind 22swg Solid 9.3kg/sqm | B3: 9.3 | D3: 73 | E3: 80 | F3: 73 | G3: 17 | H3: 15 | I3: 6200 | J3: 100 | L3: 0 | N3: Yes | O3: Steel | P3: none | Q3: Securodoor | R3: Yes | S3: 75mm lath | T3: Yes | U3: Standard, Hi usage, Hi speed(warning)
A4: 75mm 20swg, Solid 12.1kg/sqm | B4: 12.1 | D4: 73 | E4: 80 | F4: 73 | G4: 17 | H4: 10 | I4: 4600 | J4: 100 | L4: 0 | N4: no | O4: Steel | P4: none | Q4: Securodoor | R4: Yes | S4: 75mm lath | T4: Yes | U4: Standard, Hi usage, Hi speed(warning)
A5: 75mm Wind 20swg Solid 12.1kg/sqm | B5: 12.1 | D5: 73 | E5: 80 | F5: 73 | G5: 17 | H5: 15 | I5: 10000 | J5: 100 | L5: 0 | N5: Yes | O5: Steel | P5: none | Q5: Securodoor | R5: Yes | S5: 75mm lath | T5: Yes | U5: Standard, Hi usage, Hi speed(warning)
A6: 75mm 18swg, Solid 16 kg/sqm | B6: 16 | D6: 73 | E6: 80 | F6: 73 | G6: 17 | H6: 10 | I6: 4600 | J6: 100 | L6: 0 | N6: no | O6: Steel | P6: none | Q6: Securodoor | R6: Yes | S6: 75mm lath | T6: Yes | U6: Standard, Hi usage, Hi speed(warning)
A7: 75mm Wind 18swg Solid 16 kg/sqm | B7: 16 | D7: 73 | E7: 80 | F7: 73 | G7: 17 | H7: 15 | I7: 10000 | J7: 100 | L7: 0 | N7: Yes | O7: Steel | P7: none | Q7: Securodoor | R7: Yes | S7: 75mm lath | T7: Yes | U7: Standard, Hi usage, Hi speed(Max 15 RPM)
A8: 75mm 22swg, Perforated 8.3kg/sqm | B8: 8.3 | D8: 73 | E8: 80 | F8: 73 | G8: 17 | H8: 10 | I8: 4000 | J8: 100 | L8: 30 | N8: no | O8: Steel | P8: none | Q8: Securodoor | R8: Yes | S8: 75mm lath | T8: Yes | U8: Standard, Hi usage, Hi speed(Max 15 RPM)
A9: 75mm Wind 22swg, Perforated 8.3kg/sqm | B9: 8.3 | D9: 73 | E9: 80 | F9: 73 | G9: 17 | H9: 15 | I9: 4000 | J9: 100 | L9: 30 | N9: Yes | O9: Steel | P9: none | Q9: Securodoor | R9: Yes | S9: 75mm lath | T9: Yes | U9: Standard, Hi usage, Hi speed(Max 15 RPM)
A10: 75mm 20 swg, Perforated 10.5kg/sqm | B10: 10.5 | D10: 73 | E10: 80 | F10: 73 | G10: 17 | H10: 10 | I10: 4000 | J10: 100 | L10: 30 | N10: no | O10: Steel | P10: none | Q10: Securodoor | R10: Yes | S10: 75mm lath | T10: Yes | U10: Standard, Hi usage, Hi speed(Max 15 RPM)
A11: 75mm Wind 20swg, Perforated 10.5kg/sqm | B11: 10.5 | D11: 73 | E11: 80 | F11: 73 | G11: 17 | H11: 15 | I11: 8200 | J11: 100 | L11: 30 | N11: Yes | O11: Steel | P11: none | Q11: Securodoor | R11: Yes | S11: 75mm lath | T11: Yes | U11: Standard, Hi usage, Hi speed(Max 15 RPM)
A12: 75mm 18swg, Perforated 14kg/sqm | B12: 14 | D12: 73 | E12: 80 | F12: 73 | G12: 17 | H12: 10 | I12: 4000 | J12: 100 | L12: 30 | N12: no | O12: Steel | P12: none | Q12: Securodoor | R12: Yes | S12: 75mm lath | T12: Yes | U12: Standard, Hi usage, Hi speed(Max 15 RPM)
A13: 75mm Wind 18swg, Perforated 14kg/sqm | B13: 14 | D13: 73 | E13: 80 | F13: 73 | G13: 17 | H13: 15 | I13: 9000 | J13: 100 | L13: 30 | N13: Yes | O13: Steel | P13: none | Q13: Securodoor | R13: Yes | S13: 75mm lath | T13: Yes | U13: Standard, Hi usage, Hi speed(Max 15 RPM)
... A17: 75mm Wind 20swg, Brick bond 9.7kg/sqm | B17: 9.7 | D17: 73 | E17: 80 | F17: 73 | G17: 17 | H17: 15 | I17: 8200 | J17: 100 | L17: 25 | N17: Yes | O17: Steel | P17: none | Q17: Securodoor | R17: Yes | S17: 75mm lath | T17: Yes | U17: Standard, Hi usage, Hi speed(Max 15 RPM)
A18: -----------------------------------
A19: 77t 11.4 kgs/sqm | B19: 11.4 | D19: 77 | E19: 82 | F19: 77 | G19: 17 | H19: 10 | I19: 6000 | J19: 100 | L19: 0 | N19: no | O19: Steel | P19: yes | Q19: Securodoor | R19: no | S19: 77mm lath | T19: no | U19: Standard, Hi usage, Hi speed
A20: -----------------------------------
A21: 95mm WM95 13.25kg.sqm | B21: 13.25 | D21: 94 | E21: 95 | F21: 50 | G21: 25 | H21: 10 | I21: 10000 | J21: 127 | L21: 0 | N21: no | O21: Steel | P21: 3.2 | Q21: Securodoor | R21: no | S21: 95mm lath | T21: no | U21: Standard, Hi usage, Hi speed
A22: 95mm Vision WM95 12kg.sqm | B22: 12 | D22: 94 | E22: 95 | F22: 50 | G22: 25 | H22: 10 | I22: 9000 | J22: 127 | N22: no | O22: Steel | P22: yes | Q22: Securodoor | R22: no | S22: 95mm lath | T22: no | U22: Standard, Hi usage, Hi speed
A23: -----------------------------------
A24: 100mm Galv Insulated 22kg/sqm | B24: 22 | C24: 0.91 | D24: 98 | E24: 102 | G24: 25 | H24: 10 | I24: 9000 | J24: 100 | L24: 0 | N24: no | O24: Steel | P24: 4.3 | Q24: Securodoor | R24: no | S24: 100mm lath | T24: no | U24: Standard, Hi usage, Hi speed
A25: -----------------------------------
A26: CD150 4 Kgs/m2 | B26: 4 | D26: 40 | E26: 42 | F26: 130 | G26: 9 | H26: 10 | I26: 3800 | J26: 60 | N26: no | O26: Aluminium | P26: yes | Q26: SecuroShield | R26: no | S26: 150mm lath | T26: no | U26: Standard
A27: CD38 8 Kgs/m2 | B27: 8 | D27: 36 | E27: 38 | F27: 130 | G27: 9 | H27: 10 | I27: 5000 | J27: 60 | N27: no | O27: Aluminium | P27: yes | Q27: SecuroShield | R27: no | S27: 38mm lath | T27: no | U27: Standard
A28: CD38 perforated | B28: 6.5 | D28: 36 | E28: 38 | F28: 130 | G28: 9 | H28: 10 | I28: 3000 | J28: 60 | N28: no | O28: Aluminium | P28: yes | Q28: SecuroShield | R28: no | S28: 38mm lath | T28: no | U28: Standard
A29: CD38 punched | B29: 6.5 | D29: 36 | E29: 38 | F29: 130 | G29: 9 | H29: 10 | I29: 3000 | J29: 60 | N29: no | O29: Aluminium | P29: yes | Q29: SecuroShield | R29: no | S29: 38mm lath | T29: no | U29: Standard
A30: CD38 punched & glazed | B30: 7.5 | D30: 36 | E30: 38 | F30: 130 | G30: 9 | H30: 10 | I30: 3000 | J30: 60 | N30: no | O30: Aluminium | P30: yes | Q30: SecuroShield | R30: no | S30: 38mm lath | T30: no | U30: Standard
A31: CD60 9 Kgs/m2 | B31: 9 | D31: 55 | E31: 59 | F31: 170 | G31: 15 | H31: 10 | I31: 6000 | J31: 60 | N31: no | O31: Aluminium | P31: yes | Q31: SecuroShield | R31: no | S31: 60mm lath | T31: no | U31: Standard
A32: CD80 solid | B32: 9.25 | D32: 77.3 | E32: 79 | F32: 170 | G32: 19 | H32: 10 | I32: 6000 | J32: 60 | N32: no | O32: Aluminium | P32: yes | Q32: SecuroShield | R32: no | S32: 80mm lath | T32: no | U32: Standard
A33: CD80 puched | B33: 7 | D33: 77.3 | E33: 79 | F33: 170 | G33: 19 | H33: 10 | I33: 6000 | J33: 60 | N33: no | O33: Aluminium | P33: yes | Q33: SecuroShield | R33: no | S33: 80mm lath | T33: no | U33: Standard
A34: CD80 punched and glazed | B34: 8 | D34: 77.3 | E34: 79 | F34: 170 | G34: 19 | H34: 10 | I34: 6000 | J34: 60 | N34: no | O34: Aluminium | P34: yes | Q34: SecuroShield | R34: no | S34: 80mm lath | T34: no | U34: Standard
A35: CD90 7 Kgs/m2 | B35: 7 | D35: 88 | E35: 90 | F35: 170 | G35: 27 | H35: 10 | I35: 5000 | J35: 60 | N35: no | O35: Aluminium | P35: No | Q35: SecuroShield | R35: no | S35: 90mm lath | T35: no | U35: Standard
A36: -----------------------------------
A37: CD77 5 Kgs/m2 | B37: 5 | D37: 77 | E37: 79 | F37: 200 | G37: 21 | H37: 10 | I37: 5400 | J37: 60 | N37: no | O37: Aluminium | P37: yes | Q37: SecuroGlide | R37: no | S37: 77mm lath | T37: no | U37: Standard
A38: CD300 4.5 Kgs/m3 | B38: 4.5 | D38: 55 | E38: 57 | F38: 150 | G38: 14 | H38: 10 | I38: 3000 | J38: 60 | N38: no | O38: Aluminium | P38: yes | Q38: SecuroGlide | R38: no | S38: 55mm lath | T38: no | U38: Standard

Sheet Bottom lath
A1: Bottom lath name | B1: BLath weight / m length | C1: BLath height | D1: Hangdown | E1: 75mm lath | F1: 95mm lath | G1: 100mm lath | H1: 110mm lath | I1: 77mm lath | J1: 55mm lath | K1: 150mm lath | L1: 38mm lath | M1: 60mm lath | N1: 80mm lath | O1: 90mm lath | P1: Sloping type | Q1: BL image
A2: T-Rail 3.2kg/m | B2: 3.2 | C2: 65 | D2: 50 | E2: Yes | F2: No | G2: No | H2: No | I2: No | J2: No | K2: No | L2: No | M2: No | N2: No | O2: No | P2: C section
A3: T-Rail with D-rubber 5.34kg/m | B3: =B2+1.64+0.5 -> 5.34 | C3: 90 | D3: 70 | E3: Yes | F3: No | G3: No | H3: No | I3: No | J3: No | K3: No | L3: No | M3: No | N3: No | O3: No | P3: C section
A4: T-Rail with 11mm wireless-rubber 4.2kg/m | B4: =B2+0.72+0.5 -> 4.42 | C4: 110 | D4: 85 | E4: Yes | F4: No | G4: No | H4: No | I4: No | J4: No | K4: No | L4: No | M4: No | N4: No | O4: No | P4: C section
A5: T-Rail with 22mm wireless-rubber 4.2kg/m | B5: =B2+0.85+0.5 -> 4.55 | C5: 120 | D5: 95 | E5: Yes | F5: No | G5: No | H5: No | I5: No | J5: No | K5: No | L5: No | M5: No | N5: No | O5: No | P5: C section
A6: L-Rail 2.1kg/m | B6: 2.1 | C6: 65 | D6: 50 | E6: Yes | F6: No | G6: No | H6: No | I6: No | J6: No | K6: No | L6: No | M6: No | N6: No | O6: No | P6: L section
A7: L-Rail with 11mm wireless-rubber 3.32kg/m | B7: =B6+0.72+0.5 -> 3.32 | C7: 110 | D7: 85 | E7: Yes | F7: No | G7: No | H7: No | I7: No | J7: No | K7: No | L7: No | M7: No | N7: No | O7: No | P7: L section
A8: L-Rail with 22mm wireless-rubber 3.32kg/m | B8: =B6+0.85+0.5 -> 3.45 | C8: 120 | D8: 95 | E8: Yes | F8: No | G8: No | H8: No | I8: No | J8: No | K8: No | L8: No | M8: No | N8: No | O8: No | P8: L section
A9: 77t with triple chamber rubber 2kg/m | B9: 2 | C9: 112 | D9: 80 | E9: No | F9: No | G9: No | H9: No | I9: Yes | J9: No | K9: Yes | L9: No | M9: No | N9: No | O9: No | P9: 2 plates
A10: WM95 Rail and rubber [1.2kg/m] | B10: 1.2 | C10: 80 | D10: 100 | E10: No | F10: Yes | G10: No | H10: No | I10: No | J10: No | K10: No | L10: No | M10: No | N10: No | O10: No | P10: 2 plates
A11: WM95 Rail with 11mm wireless-rubber 1.54kg/m | B11: =0.82+0.72 -> 1.54 | C11: 120 | D11: 100 | E11: No | F11: Yes | G11: No | H11: No | I11: No | J11: No | K11: No | L11: No | M11: No | N11: No | O11: No | P11: 2 plates
A12: 100mm Rail with 11mm wireless-rubber 0.95kg/m | B12: 0.95 | C12: 20 | D12: 100 | E12: No | F12: No | G12: Yes | H12: No | I12: No | J12: No | K12: No | L12: No | M12: No | N12: No | O12: No | P12: 2 plates
A13: AEG + RUBBER SEAL | B13: 1.2 | C13: 58 | D13: 50 | E13: No | F13: No | G13: No | H13: No | I13: No | J13: No | K13: Yes | L13: Yes | M13: No | N13: No | O13: No | P13: 2 plates
A14: AEG/R + RUBBER SEAL | B14: 1.2 | C14: 58 | D14: 50 | E14: No | F14: No | G14: No | H14: No | I14: No | J14: No | K14: Yes | L14: Yes | M14: No | N14: No | O14: No | P14: 2 plates
A15: AEG/R+BOTTOM SLAT HANDLE | B15: 1.5 | C15: 65 | D15: 65 | E15: No | F15: No | G15: No | H15: No | I15: No | J15: No | K15: Yes | L15: Yes | M15: No | N15: No | O15: No | P15: 2 plates
A16: AEG/X + REINFORCING ANGLE | B16: 2.5 | C16: 96 | D16: 96 | E16: No | F16: No | G16: No | H16: No | I16: No | J16: Yes | K16: No | L16: No | M16: Yes | N16: Yes | O16: Yes | P16: 2 plates
A17: AEG/DW | B17: 2 | C17: 114 | D17: 114 | E17: No | F17: No | G17: No | H17: No | I17: Yes | J17: No | K17: No | L17: No | M17: No | N17: No | O17: No | P17: 2 plates

Sheet Guides
A1: ID | B1: Name | C1: Wind type | D1: Width | E1: Penetration | F1: Material | G1: 75mm lath | H1: 95mm lath | I1: 100mm lath | J1: 77mm lath | K1: 55mm lath | L1: 150mm lath | M1: 38mm lath | N1: 60mm lath | O1: 80mm lath | P1: 90mm lath | Q1: guide image | U1: Brush front | V1: Brush back | W1: associated lath | X1: Group name | Y1: Notes
A2: G65s | B2: 65 straight | C2: No | D2: 65 | E2: =D2-5 -> 60 | F2: Steel | G2: Yes | H2: No | I2: No | J2: No | K2: No | L2: No | M2: No | N2: No | O2: No | P2: No | U2: 0 | V2: 0 | W2: 75mm lath | X2: Industrial with motor, Traditional with motor
A3: G65w | B3: 65 wind | C3: Yes | D3: 65 | E3: =D3-5 -> 60 | F3: Steel | G3: Yes | H3: No | I3: No | J3: No | K3: No | L3: No | M3: No | N3: No | O3: No | P3: No | U3: 0 | V3: 0 | W3: 75mm lath | X3: Industrial with motor, Traditional with motor
A4: G100s | B4: 100 straight | C4: No | D4: 100 | E4: =D4-5 -> 95 | F4: Steel | G4: Yes | H4: No | I4: No | J4: No | K4: No | L4: No | M4: No | N4: No | O4: No | P4: No | U4: 0 | V4: 0 | W4: 75mm lath | X4: Industrial with motor, Traditional with motor
A5: G100w | B5: 100 wind | C5: Yes | D5: 100 | E5: =D5-5 -> 95 | F5: Steel | G5: Yes | H5: No | I5: No | J5: No | K5: No | L5: No | M5: No | N5: No | O5: No | P5: No | U5: 0 | V5: 0 | W5: 75mm lath | X5: Industrial with motor, Traditional with motor
A6: G80w | B6: 82 wind for 95mm | C6: Yes | D6: 82 | E6: =D6-5 -> 77 | F6: Steel | G6: No | H6: Yes | I6: No | J6: No | K6: No | L6: No | M6: No | N6: No | O6: No | P6: No | U6: 4 | V6: 4 | W6: 95mm lath | X6: Industrial with motor, Traditional with motor | Y6: name 80dr standard
A7: G78w | B7: 78 for 100mm wind | C7: Yes | D7: 78 | E7: =D7-5 -> 73 | F7: Steel | G7: No | H7: No | I7: Yes | J7: No | K7: No | L7: No | M7: No | N7: No | O7: No | P7: No | U7: 4 | V7: 4 | W7: 100mm lath | X7: Industrial with motor | Y7: CD100GU stock code
A9: H17 | B9: H17 | C9: No | D9: 45 | E9: =17-5 -> 12 | F9: Aluminium | G9: No | H9: No | I9: No | J9: No | K9: No | L9: Yes | M9: Yes | N9: No | O9: No | P9: No | W9: 38mm lath | X9: Shield
A10: H25 | B10: H25 | C10: No | D10: 53 | E10: =25-5 -> 20 | F10: Aluminium | G10: No | H10: No | I10: No | J10: No | K10: No | L10: Yes | M10: Yes | N10: No | O10: No | P10: No | W10: 38mm lath | X10: Shield
A11: H30 | B11: H30 | C11: No | D11: 60 | E11: =31-7 -> 24 | F11: Aluminium | G11: No | H11: No | I11: No | J11: No | K11: No | L11: Yes | M11: Yes | N11: No | O11: No | P11: No | W11: 38mm lath | X11: Shield
A12: H40s | B12: H40s wind | C12: Yes | D12: 70 | E12: =42-5 -> 37 | F12: Aluminium | G12: No | H12: No | I12: No | J12: No | K12: Yes | L12: Yes | M12: Yes | N12: No | O12: No | P12: No | W12: 38mm lath | X12: Shield
A13: UPH140 | B13: UPH140 | C13: No | D13: 60 | E13: =32-5 -> 27 | F13: Aluminium | G13: No | H13: No | I13: No | J13: No | K13: Yes | L13: No | M13: No | N13: Yes | O13: No | P13: Yes | X13: Shield,Glide
A14: UPH240 | B14: UPH240 | C14: No | D14: 75 | E14: =37-5 -> 32 | F14: Aluminium | G14: No | H14: No | I14: No | J14: No | K14: No | L14: No | M14: No | N14: Yes | O14: No | P14: Yes | X14: Shield
A15: UPH250 | B15: UPH250 | C15: No | D15: 90 | E15: =52-5 -> 47 | F15: Aluminium | G15: Yes | H15: No | I15: No | J15: Yes | K15: No | L15: No | M15: No | N15: Yes | O15: Yes | P15: Yes | X15: Shield,Glide

Sheet Endlock
A1: Description | B1: associated lath | C1: material | D1: weight in grams | E1: end lock offset | F1: endlock to guide inner | G1: Endlock wind type | H1: 75mm lath | I1: 95mm lath | J1: 100mm lath | K1: 77mm lath | L1: 55mm lath | M1: 150mm lath | N1: 38mm lath | O1: 60mm lath | P1: 80mm lath | Q1: 90mm lath
A2: 75mm plastic | B2: 75mm | C2: plastic | D2: 20 | E2: 10 | F2: 9 | G2: Standard | H2: Yes | I2: No | J2: No | K2: No | L2: No | M2: No | N2: No | O2: No | P2: No | Q2: No
A3: 75mm cast | B3: 75mm | C3: steel | D3: 60 | E3: 7.5 | F3: 9 | G3: Standard | H3: Yes | I3: No | J3: No | K3: No | L3: No | M3: No | N3: No | O3: No | P3: No | Q3: No
A4: 75mm wind | B4: 75mm | C4: steel | D4: 235 | E4: 19 | F4: 9 | G4: Wind | H4: Yes | I4: No | J4: No | K4: No | L4: No | M4: No | N4: No | O4: No | P4: No | Q4: No
A5: 77t plastic | B5: 77t | C5: plastic | D5: 10 | E5: 5 | F5: 9 | G5: Standard | H5: No | I5: No | J5: No | K5: Yes | L5: No | M5: No | N5: No | O5: No | P5: No | Q5: No
A6: 95mm | B6: 95mm | C6: plastic | D6: 20 | E6: 10 | F6: 9 | G6: Standard | H6: No | I6: Yes | J6: No | K6: No | L6: No | M6: No | N6: No | O6: No | P6: No | Q6: No
A7: 100mm | B7: 100mm | C7: plastic | D7: 30 | E7: 10 | F7: 9 | G7: Standard | H7: No | I7: No | J7: Yes | K7: No | L7: No | M7: No | N7: No | O7: No | P7: No | Q7: No
A8: ---- | B8: ----
A9: 150 plastic | B9: CD150 | C9: plastic | D9: 2 | E9: 5 | F9: 5 | G9: Standard | H9: No | I9: No | J9: Yes | K9: No | L9: No | M9: Yes | N9: No | O9: No | P9: No | Q9: No
A10: 38 plastic | B10: CD38 | C10: plastic | D10: 2 | E10: 5 | F10: 5 | G10: Standard | H10: No | I10: No | J10: No | K10: No | L10: No | M10: Yes | N10: Yes | O10: No | P10: No | Q10: No
A11: 38 plastic wind | B11: CD38 | D11: 5 | E11: 5 | F11: 5 | G11: Wind | H11: No | I11: No | J11: No | K11: No | L11: No | M11: Yes | N11: Yes | O11: No | P11: No | Q11: No
A12: 60 plastic | B12: CD60 | C12: plastic | D12: 6 | E12: 5 | F12: 5 | G12: Standard | H12: No | I12: No | J12: No | K12: No | L12: No | M12: No | N12: No | O12: Yes | P12: No | Q12: No
A13: 80 plastic | B13: CD80 | C13: plastic | D13: 8 | E13: 5 | F13: 5 | G13: Standard | H13: No | I13: No | J13: No | K13: No | L13: No | M13: No | N13: No | O13: No | P13: Yes | Q13: No
A14: 90 fixing | B14: CD90 | C14: plastic | D14: 5 | E14: 5 | F14: 5 | G14: Standard | H14: No | I14: No | J14: No | K14: No | L14: No | M14: No | N14: No | O14: No | P14: No | Q14: Yes
A15: 77 plastic | B15: CD77 | C15: plastic | D15: 10 | E15: 5 | F15: 5 | G15: Standard | H15: No | I15: No | J15: No | K15: Yes | L15: No | M15: No | N15: No | O15: No | P15: No | Q15: No
A16: 55 plastic | B16: CD300 | C16: plastic | D16: 6 | E16: 5 | F16: 5 | G16: Standard | H16: No | I16: No | J16: No | K16: No | L16: Yes | M16: No | N16: No | O16: No | P16: No | Q16: No
B21: New cast endlock? | D21: 92

Sheet Axles
A1: Name | B1: Shape | C1: Alternate name | D1: Diameter | E1: Wall Thickness | F1: ID | G1: Material grade | H1: Density (kg/m3) | I1: Moment of inertia | J1: SWS stocked | K1: Stock code | L1: inches | M1: Chain opp | N1: stock length | O1: Price per m | P1: Grade | Q1: Weight /m (kg)
A2: 60mm x 1.2 | B2: Octagonal | C2: 60mm Oct | D2: 60 | E2: 1.2 | F2: =D2-(E2*2) -> 57.6 | G2: 210000 | H2: 7850 | J2: Yes | M2: Yes
A3: 70mm x 1.2 | B3: Octagonal | C3: 70mm Oct | D3: 70 | E3: 1.2 | F3: =D3-(E3*2) -> 67.6 | G3: 210000 | H3: 7850 | J3: Yes | M3: Yes
A4: 70mm 1.5 | B4: Octagonal | C4: 70mm Oct | D4: 70 | E4: 1.5 | F4: =D4-(E4*2) -> 67 | G4: 210000 | H4: 7850 | J4: Yes | M4: Yes
A5: 102 x 1.5 | B5: Circular | C5: 4" 16 g | D5: 101.6 | E5: 1.5 | F5: =D5-(E5*2) -> 98.6 | G5: 210000 | H5: 7850 | J5: Yes | K5: AX130R5 | L5: =D5/25.4 -> 4 | M5: Yes | N5: 8 | P5: ERW
A6: 102 x 3 | B6: Circular | C6: 4" 10g | D6: 101.6 | E6: 3 | F6: =D6-(E6*2) -> 95.6 | G6: 210000 | H6: 7850 | J6: Yes | K6: AX130R2 | L6: =D6/25.4 -> 4 | M6: Yes | N6: 8 | P6: S235JR EN10219
A7: 127 x 3.25 | B7: Circular | C7: 5" 10g | D7: 127 | E7: 3.25 | F7: =D7-(E7*2) -> 120.5 | G7: 210000 | H7: 7850 | J7: Yes | K7: AX131R9 | L7: =D7/25.4 -> 5 | M7: Yes | N7: 8 | P7: ERW
A8: 139.7 x 5 | B8: Circular | C8: 5.5" 6g | D8: 139.7 | E8: 5 | F8: =D8-(E8*2) -> 129.7 | G8: 210000 | H8: 7850 | J8: Yes | K8: AX132R2 | L8: =D8/25.4 -> 5.5 | M8: No | N8: 7.5 | P8: S235JR EN10219
A9: 168.3 x 5 | B9: Circular | C9: 6 5/8th" 6g | D9: 168.3 | E9: 5 | F9: =D9-(E9*2) -> 158.3 | G9: 210000 | H9: 7850 | J9: Yes | K9: AX134R1 | L9: =D9/25.4 -> 6.6259843 | M9: No | N9: 7.5 | P9: S235JR EN10219
A10: 193.7 x 6.3 | B10: Circular | C10: 7 5/8th" 3g | D10: 193.7 | E10: 6.3 | F10: =D10-(E10*2) -> 181.1 | G10: 210000 | H10: 7850 | J10: Yes | K10: AX134R0 | L10: =D10/25.4 -> 7.6259843 | M10: No | N10: ns12 | P10: S355J2H EN10210
A11: 219.1 x 6.3 | B11: Circular | C11: 8 5/8" 3g | D11: 219.1 | E11: 6.3 | F11: =D11-(E11*2) -> 206.5 | G11: 210000 | H11: 7850 | J11: Yes | K11: AX133R0 | L11: =D11/25.4 -> 8.6259843 | M11: No | N11: ns12 | P11: S355J2H EN10210
A12: 273 x 6.3 | B12: Circular | C12: 10 3/4" 3g | D12: 273 | E12: 6.3 | F12: =D12-(E12*2) -> 260.4 | G12: 210000 | H12: 7850 | J12: Yes | L12: =D12/25.4 -> 10.748031 | M12: No | N12: ns12 | P12: S355J2H EN10210
A13: 273 x 8 | B13: Circular | C13: 10 3/4" 8mm | D13: 273 | E13: 8 | F13: =D13-(E13*2) -> 257 | G13: 210000 | H13: 7850 | J13: Yes | M13: No | N13: ns12

Sheet Coiling data
B3: Internal coil per wrap | C3: External coil per wrap
B4: 1st 145mm | C4: 1st 137mm | E4: 145 | G4: 137
B5: 2nd 130mm | C5: 2nd 122mm | E5: 130 | F5: =E4-E5 -> 15 | G5: 122 | H5: =G4-G5 -> 15
B6: 3rd 120mm | C6: 3rd 110mm | E6: 120 | F6: =E5-E6 -> 10 | G6: 110 | H6: =G5-G6 -> 12
B7: 4th 110mm | C7: 4th 92mm | E7: 110 | F7: =E6-E7 -> 10 | G7: 92 | H7: =G6-G7 -> 18
B8: 5th 95mm | C8: 5th 75mm | E8: 95 | F8: =E7-E8 -> 15 | G8: 75 | H8: =G7-G8 -> 17
B9: 6th 75mm | C9: 6th 61mm | E9: 75 | F9: =E8-E9 -> 20 | G9: 61 | H9: =G8-G9 -> 14
B10: 7th 65mm | C10: 7th 48mm | E10: 65 | F10: =E9-E10 -> 10 | G10: 48 | H10: =G9-G10 -> 13
B11: 8th 55mm | C11: 8th 35mm | E11: 55 | F11: =E10-E11 -> 10 | G11: 35 | H11: =G10-G11 -> 13
C13: Average lath width | F13: =AVERAGE(F5:F12) -> 12.857143 | H13: =AVERAGE(H5:H12) -> 14.571429

Sheet Disc size
A1: Barrel size | B1: Barrel size mm | C1: Barrel ID | D1: Disc to barrel gap | E1: Disc o/d | F1: Disc thickness | G1: Disc bore | H1: Stock ref | I1: SWS stock | J1: Supplier | K1: Supplier ref | L1: circ | O1: Weight of disc | P1: Comments
A2: 4" 16 | B2: 102 x 1.6 | C2: =Axles!F4 -> 67 | D2: =(E2-C2)/2 -> 15.25 | E2: 97.5 | F2: 5 | G2: 18 | I2: square | J2: GFA | L2: =PI() * G2 -> 56.548668 | N2: =L2/25.4 -> 2.2263255 | O2: =((PI()/4) * (E2^2 - G2^2) * F2 * 0.00785)/1000 -> 0.2830601
A3: 4" 16 | B3: 102 x 1.6 | C3: =Axles!F5 -> 98.6 | D3: =(E3-C3)/2 -> -0.55 | E3: 97.5 | F3: 5 | G3: 25.4 | J3: GFA | L3: =PI() * G3 -> 79.796453 | N3: =L3/25.4 -> 3.1415927 | O3: =((PI()/4) * (E3^2 - G3^2) * F3 * 0.00785)/1000 -> 0.27315974
A4: 4" 16 | B4: 102 x 1.6 | C4: =Axles!F5 -> 98.6 | D4: =(E4-C4)/2 -> -0.55 | E4: 97.5 | F4: 5 | G4: 30 | I4: SD141B2 | J4: GFA | L4: =PI() * G4 -> 94.24778 | N4: =L4/25.4 -> 3.7105425 | O4: =((PI()/4) * (E4^2 - G4^2) * F4 * 0.00785)/1000 -> 0.26530382
A5: 4" 16 | B5: 102 x 1.6 | C5: =Axles!F5 -> 98.6 | D5: =(E5-C5)/2 -> -0.55 | E5: 97.5 | F5: 5 | G5: 35 | J5: GFA | L5: =PI() * G5 -> 109.95574 | N5: =L5/25.4 -> 4.3289663 | O5: =((PI()/4) * (E5^2 - G5^2) * F5 * 0.00785)/1000 -> 0.25528508
A6: 4" 10 | B6: 102 x 3.6 | C6: =Axles!F6 -> 95.6 | D6: =(E6-C6)/2 -> -1.3 | E6: 93 | F6: 5 | G6: 25.4 | J6: GFA | L6: =PI() * G6 -> 79.796453 | N6: =L6/25.4 -> 3.1415927 | O6: =((PI()/4) * (E6^2 - G6^2) * F6 * 0.00785)/1000 -> 0.2467334
A7: 4" 10 | B7: 102 x 3.6 | C7: =Axles!F6 -> 95.6 | D7: =(E7-C7)/2 -> -1.3 | E7: 93 | F7: 5 | G7: 30 | I7: SD142B1 | J7: GFA | L7: =PI() * G7 -> 94.24778 | N7: =L7/25.4 -> 3.7105425 | O7: =((PI()/4) * (E7^2 - G7^2) * F7 * 0.00785)/1000 -> 0.23887748
A8: 4" 10 | B8: 102 x 3.6 | C8: =Axles!F6 -> 95.6 | D8: =(E8-C8)/2 -> -1.3 | E8: 93 | F8: 5 | G8: 35 | J8: GFA | L8: =PI() * G8 -> 109.95574 | N8: =L8/25.4 -> 4.3289663 | O8: =((PI()/4) * (E8^2 - G8^2) * F8 * 0.00785)/1000 -> 0.22885874
A9: 4" 10 | B9: 102 x 3.6 | C9: =Axles!F6 -> 95.6 | D9: =(E9-C9)/2 -> -1.3 | E9: 93 | F9: 5 | G9: 40 | I9: MT229M2 | J9: GFA | L9: =PI() * G9 -> 125.66371 | N9: =L9/25.4 -> 4.94739 | O9: =((PI()/4) * (E9^2 - G9^2) * F9 * 0.00785)/1000 -> 0.21729866
A10: 4" 10 | B10: 102 x 3.6 | C10: =Axles!F6 -> 95.6 | D10: =(E10-C10)/2 -> -1.3 | E10: 93 | F10: 5 | G10: 45 | J10: GFA | L10: =PI() * G10 -> 141.37167 | N10: =L10/25.4 -> 5.5658138 | O10: =((PI()/4) * (E10^2 - G10^2) * F10 * 0.00785)/1000 -> 0.20419724
A11: 5" 10g | B11: 127 x 3.2 | C11: =Axles!F7 -> 120.5 | D11: =(E11-C11)/2 -> -0.25 | E11: 120 | F11: 5 | G11: 25.4 | J11: GFA | L11: =PI() * G11 -> 79.796453 | N11: =L11/25.4 -> 3.1415927 | O11: =((PI()/4) * (E11^2 - G11^2) * F11 * 0.00785)/1000 -> 0.42401877
A12: 5" 10g | B12: 127 x 3.2 | C12: =Axles!F7 -> 120.5 | D12: =(E12-C12)/2 -> -0.25 | E12: 120 | F12: 5 | G12: 30 | I12: SD141B3 | J12: GFA | L12: =PI() * G12 -> 94.24778 | N12: =L12/25.4 -> 3.7105425 | O12: =((PI()/4) * (E12^2 - G12^2) * F12 * 0.00785)/1000 -> 0.41616285
A13: 5" 10g | B13: 127 x 3.2 | C13: =Axles!F7 -> 120.5 | D13: =(E13-C13)/2 -> -0.25 | E13: 120 | F13: 5 | G13: 35 | J13: GFA | L13: =PI() * G13 -> 109.95574 | N13: =L13/25.4 -> 4.3289663 | O13: =((PI()/4) * (E13^2 - G13^2) * F13 * 0.00785)/1000 -> 0.40614412
A14: 5" 10g | B14: 127 x 3.2 | C14: =Axles!F7 -> 120.5 | D14: =(E14-C14)/2 -> -0.25 | E14: 120 | F14: 5 | G14: 40 | I14: MT204M1 | J14: GFA | L14: =PI() * G14 -> 125.66371 | N14: =L14/25.4 -> 4.94739 | O14: =((PI()/4) * (E14^2 - G14^2) * F14 * 0.00785)/1000 -> 0.39458404
A15: 5" 10g | B15: 127 x 3.2 | C15: =Axles!F7 -> 120.5 | D15: =(E15-C15)/2 -> -0.25 | E15: 120 | F15: 5 | G15: 45 | J15: GFA | L15: =PI() * G15 -> 141.37167 | N15: =L15/25.4 -> 5.5658138 | O15: =((PI()/4) * (E15^2 - G15^2) * F15 * 0.00785)/1000 -> 0.38148261
A16: 5.5" 6g | B16: 139 x 4.8 | C16: =Axles!F8 -> 129.7 | D16: =(E16-C16)/2 -> -0.6 | E16: 128.5 | F16: 5 | G16: 30 | I16: SD141B4 | J16: GFA | L16: =PI() * G16 -> 94.24778 | N16: =L16/25.4 -> 3.7105425 | O16: =((PI()/4) * (E16^2 - G16^2) * F16 * 0.00785)/1000 -> 0.48127692
A17: 5.5" 6g | B17: 139 x 4.8 | C17: =Axles!F8 -> 129.7 | D17: =(E17-C17)/2 -> -0.6 | E17: 128.5 | F17: 5 | G17: 35 | J17: GFA | L17: =PI() * G17 -> 109.95574 | N17: =L17/25.4 -> 4.3289663 | O17: =((PI()/4) * (E17^2 - G17^2) * F17 * 0.00785)/1000 -> 0.47125819
A18: 5.5" 6g | B18: 139 x 4.8 | C18: =Axles!F8 -> 129.7 | D18: =(E18-C18)/2 -> -0.6 | E18: 128.5 | F18: 5 | G18: 40 | I18: MT205M1 | J18: GFA | L18: =PI() * G18 -> 125.66371 | N18: =L18/25.4 -> 4.94739 | O18: =((PI()/4) * (E18^2 - G18^2) * F18 * 0.00785)/1000 -> 0.45969811
A19: 5.5" 6g | B19: 139 x 4.8 | C19: =Axles!F8 -> 129.7 | D19: =(E19-C19)/2 -> -0.6 | E19: 128.5 | F19: 5 | G19: 45 | J19: GFA | L19: =PI() * G19 -> 141.37167 | N19: =L19/25.4 -> 5.5658138 | O19: =((PI()/4) * (E19^2 - G19^2) * F19 * 0.00785)/1000 -> 0.44659669
A20: 5.5" 6g | B20: 139 x 4.8 | C20: =Axles!F8 -> 129.7 | D20: =(E20-C20)/2 -> -0.6 | E20: 128.5 | F20: 5 | G20: 55 | I20: MT232M1 | J20: GFA | L20: =PI() * G20 -> 172.7876 | N20: =L20/25.4 -> 6.8026613 | O20: =((PI()/4) * (E20^2 - G20^2) * F20 * 0.00785)/1000 -> 0.41576981
A21: 6 5/8th" 6g | B21: 168 x 4.8 | C21: =Axles!F9 -> 158.3 | D21: =(E21-C21)/2 -> -1.65 | E21: 155 | F21: 8 | G21: 40 | I21: ?? | J21: GFA | L21: =PI() * G21 -> 125.66371 | N21: =L21/25.4 -> 4.94739 | O21: =((PI()/4) * (E21^2 - G21^2) * F21 * 0.00785)/1000 -> 1.1060684
A22: 6 5/8th" 6g | B22: 168 x 4.8 | C22: =Axles!F9 -> 158.3 | D22: =(E22-C22)/2 -> -1.65 | E22: 155 | F22: 8 | G22: 45 | J22: GFA | L22: =PI() * G22 -> 141.37167 | N22: =L22/25.4 -> 5.5658138 | O22: =((PI()/4) * (E22^2 - G22^2) * F22 * 0.00785)/1000 -> 1.0851061
A23: 6 5/8th" 6g | B23: 168 x 4.8 | C23: =Axles!F9 -> 158.3 | D23: =(E23-C23)/2 -> -1.65 | E23: 155 | F23: 8 | G23: 55 | I23: ?? | J23: GFA | L23: =PI() * G23 -> 172.7876 | N23: =L23/25.4 -> 6.8026613 | O23: =((PI()/4) * (E23^2 - G23^2) * F23 * 0.00785)/1000 -> 1.0357831
A24: 6 5/8th" 6g | B24: 168 x 4.8 | C24: =Axles!F9 -> 158.3 | D24: =(E24-C24)/2 -> -0.15 | E24: 158 | F24: 8 | G24: 30 | J24: GFA | L24: =PI() * G24 -> 94.24778 | N24: =L24/25.4 -> 3.7105425 | O24: =((PI()/4) * (E24^2 - G24^2) * F24 * 0.00785)/1000 -> 1.1869088
A25: 6 5/8th" 6g | B25: 168 x 4.8 | C25: =Axles!F9 -> 158.3 | D25: =(E25-C25)/2 -> -0.15 | E25: 158 | F25: 8 | G25: 35 | J25: GFA | L25: =PI() * G25 -> 109.95574 | N25: =L25/25.4 -> 4.3289663 | O25: =((PI()/4) * (E25^2 - G25^2) * F25 * 0.00785)/1000 -> 1.1708788
A26: 6 5/8th" 6g | B26: 168 x 4.8 | C26: =Axles!F9 -> 158.3 | D26: =(E26-C26)/2 -> -0.15 | E26: 158 | F26: 8 | G26: 40 | I26: MT233M1 | J26: GFA | L26: =PI() * G26 -> 125.66371 | N26: =L26/25.4 -> 4.94739 | O26: =((PI()/4) * (E26^2 - G26^2) * F26 * 0.00785)/1000 -> 1.1523827
A27: 6 5/8th" 6g | B27: 168 x 4.8 | C27: =Axles!F9 -> 158.3 | D27: =(E27-C27)/2 -> -0.15 | E27: 158 | F27: 8 | G27: 45 | J27: GFA | L27: =PI() * G27 -> 141.37167 | N27: =L27/25.4 -> 5.5658138 | O27: =((PI()/4) * (E27^2 - G27^2) * F27 * 0.00785)/1000 -> 1.1314204
A28: 6 5/8th" 6g | B28: 168 x 4.8 | C28: =Axles!F9 -> 158.3 | D28: =(E28-C28)/2 -> -0.15 | E28: 158 | F28: 8 | G28: 55 | I28: ??? | J28: GFA | L28: =PI() * G28 -> 172.7876 | N28: =L28/25.4 -> 6.8026613 | O28: =((PI()/4) * (E28^2 - G28^2) * F28 * 0.00785)/1000 -> 1.0820974
A29: 6 5/8th" 6g | B29: 168 x 4.8 | C29: =Axles!F9 -> 158.3 | D29: =(E29-C29)/2 -> 1.35 | E29: 161 | F29: 8 | G29: 30 | J29: GFA | L29: =PI() * G29 -> 94.24778 | N29: =L29/25.4 -> 3.7105425 | O29: =((PI()/4) * (E29^2 - G29^2) * F29 * 0.00785)/1000 -> 1.2341109
A30: 6 5/8th" 6g | B30: 168 x 4.8 | C30: =Axles!F9 -> 158.3 | D30: =(E30-C30)/2 -> 1.35 | E30: 161 | F30: 8 | G30: 35 | J30: GFA | L30: =PI() * G30 -> 109.95574 | N30: =L30/25.4 -> 4.3289663 | O30: =((PI()/4) * (E30^2 - G30^2) * F30 * 0.00785)/1000 -> 1.2180809
A31: 6 5/8th" 6g | B31: 168 x 4.8 | C31: =Axles!F9 -> 158.3 | D31: =(E31-C31)/2 -> 1.35 | E31: 161 | F31: 8 | G31: 40 | I31: ??? | J31: GFA | L31: =PI() * G31 -> 125.66371 | N31: =L31/25.4 -> 4.94739 | O31: =((PI()/4) * (E31^2 - G31^2) * F31 * 0.00785)/1000 -> 1.1995848
A32: 6 5/8th" 6g | B32: 168 x 4.8 | C32: =Axles!F9 -> 158.3 | D32: =(E32-C32)/2 -> 1.35 | E32: 161 | F32: 8 | G32: 45 | J32: GFA | L32: =PI() * G32 -> 141.37167 | N32: =L32/25.4 -> 5.5658138 | O32: =((PI()/4) * (E32^2 - G32^2) * F32 * 0.00785)/1000 -> 1.1786225
A33: 6 5/8th" 6g | B33: 168 x 4.8 | C33: =Axles!F9 -> 158.3 | D33: =(E33-C33)/2 -> 1.35 | E33: 161 | F33: 8 | G33: 55 | I33: ??? | J33: GFA | L33: =PI() * G33 -> 172.7876 | N33: =L33/25.4 -> 6.8026613 | O33: =((PI()/4) * (E33^2 - G33^2) * F33 * 0.00785)/1000 -> 1.1292995
A34: 7 5/8th" 3g | B34: 193 x 6.3 | C34: =Axles!F10 -> 181.1 | D34: =(E34-C34)/2 -> -0.55 | E34: 180 | F34: 8 | G34: 40 | I34: MT245M9 | J34: GFA | L34: =PI() * G34 -> 125.66371 | N34: =L34/25.4 -> 4.94739 | O34: =((PI()/4) * (E34^2 - G34^2) * F34 * 0.00785)/1000 -> 1.5191485
A35: 7 5/8th" 3g | B35: 193 x 6.3 | C35: =Axles!F10 -> 181.1 | D35: =(E35-C35)/2 -> -0.55 | E35: 180 | F35: 8 | G35: 45 | J35: GFA | L35: =PI() * G35 -> 141.37167 | N35: =L35/25.4 -> 5.5658138 | O35: =((PI()/4) * (E35^2 - G35^2) * F35 * 0.00785)/1000 -> 1.4981863
A36: 7 5/8th" 3g | B36: 193 x 6.3 | C36: =Axles!F10 -> 181.1 | D36: =(E36-C36)/2 -> -0.55 | E36: 180 | F36: 8 | G36: 50 | J36: GFA | L36: =PI() * G36 -> 157.07963 | N36: =L36/25.4 -> 6.1842375 | O36: =((PI()/4) * (E36^2 - G36^2) * F36 * 0.00785)/1000 -> 1.4747578
A37: 7 5/8th" 3g | B37: 193 x 6.3 | C37: =Axles!F10 -> 181.1 | D37: =(E37-C37)/2 -> -0.55 | E37: 180 | F37: 8 | G37: 55 | I37: ?? | J37: GFA | L37: =PI() * G37 -> 172.7876 | N37: =L37/25.4 -> 6.8026613 | O37: =((PI()/4) * (E37^2 - G37^2) * F37 * 0.00785)/1000 -> 1.4488633
A38: 7 5/8th" 3g | B38: 193 x 6.3 | C38: =Axles!F10 -> 181.1 | D38: =(E38-C38)/2 -> -0.55 | E38: 180 | F38: 8 | G38: 60 | J38: GFA | L38: =PI() * G38 -> 188.49556 | N38: =L38/25.4 -> 7.421085 | O38: =((PI()/4) * (E38^2 - G38^2) * F38 * 0.00785)/1000 -> 1.4205025
A39: 8 5/8" 3g | B39: 219 x 5.9 | C39: =Axles!F11 -> 206.5 | D39: =(E39-C39)/2 -> -3.75 | E39: 199 | F39: 8 | G39: 50 | J39: GFA | L39: =PI() * G39 -> 157.07963 | N39: =L39/25.4 -> 6.1842375 | O39: =((PI()/4) * (E39^2 - G39^2) * F39 * 0.00785)/1000 -> 1.8299328
A40: 8 5/8" 3g | B40: 219 x 5.9 | C40: =Axles!F11 -> 206.5 | D40: =(E40-C40)/2 -> -3.75 | E40: 199 | F40: 8 | G40: 55 | J40: GFA | L40: =PI() * G40 -> 172.7876 | N40: =L40/25.4 -> 6.8026613 | O40: =((PI()/4) * (E40^2 - G40^2) * F40 * 0.00785)/1000 -> 1.8040382
...

Sheet Motors
A1: Name | B1: Manufacturer | C1: Torque (Nm) min | D1: Torque (Nm) max | E1: Usage type | F1: RPM | G1: Voltage | H1: Mounting type | I1: Head offset | J1: Motor Total Length | K1: Tube diameter | L1: Driveshaft diameter mm | M1: Requires additional saftey brake | N1: Manual override | O1: Limit turn | P1: Cycles Per Hour | Q1: Weight | R1: Wattage | S1: SWS Code | T1: Motor Image | U1: Motor price | V1: Comments | W1: Motor width | X1: Motor height 1 | Y1: Motor height 2 | Z1: Motor depth 1 | AA1: Motor depth 2
A2: NRG 50 | B2: Ellard | C2: 0 | D2: 50 | E2: Standard | F2: 12 | G2: 230 | H2: Tubular | I2: 26 | J2: 605 | K2: 45 | L2: N/A | M2: Yes | N2: No | O2: 22 | Q2: 3 | R2: 310
A3: NRG 50 with override | B3: Ellard | C3: 0 | D3: 50 | E3: Standard | F3: 12 | G3: 230 | H3: Tubular | I3: 23 | J3: 544 | K3: 45 | L3: N/A | M3: Yes | N3: Yes | O3: 22 | Q3: 3.3 | R3: 310
A4: NRG 100 | B4: Ellard | C4: 50.01 | D4: 100 | E4: Standard | F4: 12 | G4: 230 | H4: Tubular | I4: 32 | K4: 59 | L4: N/A | M4: Yes | N4: No | O4: 22 | Q4: 5 | R4: 345
A5: NRG 100 with override | B5: Ellard | C5: 50.01 | D5: 100 | E5: Standard | F5: 12 | G5: 230 | H5: Tubular | I5: 41.5 | K5: 59 | L5: N/A | M5: Yes | N5: Yes | O5: 22 | Q5: 5.2 | R5: 345
A6: NRG 150 with override | B6: Ellard | C6: 100.01 | D6: 150 | E6: Standard | F6: 10 | G6: 230 | H6: Tubular | I6: 30 | K6: 59 | L6: N/A | M6: Yes | N6: Yes | O6: 22 | Q6: 8.3 | R6: 390
A7: NRG 230 with override | B7: Ellard | C7: 150.01 | D7: 230 | E7: Standard | F7: 6 | G7: 230 | H7: Tubular | I7: 48.5 | K7: 92 | L7: N/A | M7: Yes | N7: Yes | O7: 22 | Q7: 12 | R7: 570
A8: NRG 350 with override | B8: Ellard | C8: 230.01 | D8: 350 | E8: Standard | F8: 7 | G8: 230 | H8: Tubular | I8: 48.5 | K8: 92 | L8: N/A | M8: Yes | N8: Yes | O8: 22 | Q8: 14 | R8: 670
A9: Eurodrive 500 | B9: Marantec | C9: =D8+0.01 -> 350.01 | D9: 500 | E9: Standard | F9: 7 | G9: 230 | H9: Tubular | I9: 65 | K9: 119.5 | M9: Yes | N9: Yes | O9: 28 | R9: 1650
A10: T845M | B10: Simu | C10: =D8+0.01 -> 350.01 | D10: 450 | E10: Standard | F10: 8 | G10: 230 | H10: Tubular | I10: 85 | K10: 89 | L10: N/A | M10: Yes | N10: No | Q10: 16 | R10: 1200
A11: T960M | B11: Simu | C11: =D10+0.01 -> 450.01 | D11: 600 | E11: Standard | F11: 9 | G11: 230 | H11: Tubular | I11: 83 | K11: 89 | L11: N/A | M11: Yes | N11: No | Q11: 19 | R11: 920
A12: - | B12: - | C12: - | D12: - | H12: -- | N12: --
A13: Jet 10 | B13: Somfy | C13: 0 | D13: 10 | E13: Standard | F13: 32 | G13: 230 | H13: Tubular | I13: 23 | J13: 555 | K13: 48 | L13: N/A | M13: Yes | N13: No | O13: 46 | Q13: 2.44 | R13: 160
A14: Meteor 20 CSI | B14: Somfy | C14: =D13+0.01 -> 10.01 | D14: 20 | E14: Standard | F14: 17 | G14: 230 | H14: Tubular | I14: 28 | J14: 774 | K14: 48 | L14: N/A | M14: Yes | N14: Yes | O14: 34 | Q14: 2.76 | R14: 160
A15: Gemini 25 | B15: Somfy | C15: =D14+0.01 -> 20.01 | D15: 25 | E15: Standard | F15: 17 | G15: 230 | H15: Tubular | J15: 663 | K15: 48 | L15: N/A | M15: Yes | N15: No | O15: 46 | Q15: 3.09 | R15: 180
A16: Helios 30 | B16: Somfy | C16: =D15+0.01 -> 25.01 | D16: 30 | E16: Standard | F16: 12 | G16: 230 | H16: Tubular | K16: 48 | L16: N/A | M16: Yes | N16: Yes | O16: 46 | Q16: 3.2 | R16: 240
A17: Helios 30 CSI | B17: Somfy | C17: =C16 -> 25.01 | D17: 30 | E17: Standard | F17: 17 | G17: 230 | H17: Tubular | K17: 48 | L17: N/A | M17: Yes | N17: Yes | O17: 34 | Q17: 3.2 | R17: 240
A18: Apollo 35 | B18: Somfy | C18: =D16+0.01 -> 30.01 | D18: 35 | E18: Standard | F18: 17 | G18: 230 | H18: Tubular | K18: 48 | L18: N/A | M18: Yes | N18: No | O18: 46 | Q18: 3.38 | R18: 270
A19: Mariner 40 CSI | B19: Somfy | C19: =D18+0.01 -> 35.01 | D19: 40 | E19: Standard | F19: 17 | G19: 230 | H19: Tubular | K19: 48 | L19: N/A | M19: Yes | N19: Yes | O19: 34 | Q19: 3.38 | R19: 270
A20: Vectran 50 | B20: Somfy | C20: =D19+0.01 -> 40.01 | D20: 50 | E20: Standard | F20: 12 | G20: 230 | H20: Tubular | K20: 48 | L20: N/A | M20: Yes | N20: No | O20: 46 | Q20: 3.09 | R20: 240
A21: ORION 55 CSI | B21: Somfy | C21: =D20+0.01 -> 50.01 | D21: 55 | E21: Standard | F21: 17 | G21: 230 | H21: Tubular | J21: 800 | K21: 60 | L21: N/A | M21: Yes | N21: Yes | O21: 34 | Q21: 4.17 | R21: 290
A22: Vega 60 CSI | B22: Somfy | C22: =D21+0.01 -> 55.01 | D22: 60 | E22: Standard | F22: 12 | G22: 230 | H22: Tubular | J22: 646 | K22: 60 | L22: N/A | M22: Yes | N22: Yes | O22: 34 | Q22: 3.92 | R22: 320
A23: Sirius 80 CSI | B23: Somfy | C23: =D22+0.01 -> 60.01 | D23: 80 | E23: Standard | F23: 12 | G23: 230 | H23: Tubular | K23: 60 | L23: N/A | M23: Yes | N23: Yes | O23: 34 | Q23: 4.19 | R23: 290
A24: Jupiter 85 | B24: Somfy | C24: =D23+0.01 -> 80.01 | D24: 85 | E24: Standard | F24: 17 | G24: 230 | H24: Tubular | K24: 60 | L24: N/A | M24: Yes | N24: No | O24: 34 | Q24: 4.45 | R24: 450
A25: Titan 100 CSI | B25: Somfy | C25: =D24+0.01 -> 85.01 | D25: 100 | E25: Standard | F25: 12 | G25: 230 | H25: Tubular | J25: 681 | K25: 60 | L25: N/A | M25: Yes | N25: Yes | O25: 34 | Q25: 4.68 | R25: 410
A26: Taurus 120 CSI | B26: Somfy | C26: =D25+0.01 -> 100.01 | D26: 120 | E26: Standard | F26: 12 | G26: 230 | H26: Tubular | J26: 681 | K26: 60 | L26: N/A | M26: Yes | N26: Yes | O26: 34 | Q26: 4.45 | R26: 450
A27: - | B27: - | C27: - | D27: - | H27: -- | N27: --
A28: - | B28: - | H28: -- | N28: --
A29: DDO 170 | B29: Ellard | C29: 0 | D29: 170 | E29: Standard | F29: 12 | G29: 415 | H29: Direct drive | I29: N/A | K29: N/A | L29: 30 | M29: No | N29: Yes | R29: 900 | S29: MT417M3
A30: DDO 260 | B30: Ellard | C30: 170.01 | D30: 260 | E30: Standard | F30: 12 | G30: 415 | H30: Direct drive | I30: N/A | K30: N/A | L30: 40 | M30: No | N30: Yes | R30: 900 | S30: MT426M3
A31: DDO 350 | B31: Ellard | C31: 260.01 | D31: 350 | E31: Standard | F31: 12 | G31: 415 | H31: Direct drive | I31: N/A | K31: N/A | L31: 40 | M31: No | N31: Yes | R31: 900 | S31: MT435M3
A32: DD0 500 | B32: Ellard | C32: 351.01 | D32: 500 | E32: Standard | F32: 12 | G32: 415 | H32: Direct drive | I32: N/A | K32: N/A | L32: 40 | M32: No | N32: Yes | R32: 900 | S32: MT450M3
A33: DD0 650 | B33: Ellard | C33: 500.01 | D33: 650 | E33: Standard | F33: 12 | G33: 415 | H33: Direct drive | I33: N/A | K33: N/A | L33: 55 | M33: No | N33: Yes | R33: 1800 | S33: MT465M3
A34: DDO 750 | B34: Ellard | C34: 650.01 | D34: 750 | E34: Standard | F34: 12 | G34: 415 | H34: Direct drive | I34: N/A | K34: N/A | L34: 55 | M34: No | N34: Yes | R34: 1800 | S34: MT475M3
A35: DDO 1000 | B35: Ellard | C35: 750.01 | D35: 1000 | E35: Standard | F35: 9 | G35: 415 | H35: Direct drive | I35: N/A | K35: N/A | L35: 55 | M35: No | N35: Yes | R35: 2500 | S35: MT410M3
A36: - | B36: - | C36: - | D36: - | H36: -- | N36: --
A37: MDF 20-15-12 HD | B37: Marantec | C37: 0 | D37: 150 | E37: Standard | F37: 12 | G37: 415 | H37: Direct drive | I37: N/A | K37: N/A | L37: 30 | M37: No | N37: Yes | P37: 30 | R37: 550
A38: MDF 20-22-12 | B38: Marantec | C38: =D37+0.01 -> 150.01 | D38: 220 | E38: Standard | F38: 12 | G38: 415 | H38: Direct drive | I38: N/A | K38: N/A | L38: 30 | M38: No | N38: Yes | P38: 20 | R38: 750 | S38: MT822M3
A39: MDF 30-30-12 | B39: Marantec | C39: =D38+0.01 -> 220.01 | D39: 300 | E39: Standard | F39: 12 | G39: 415 | H39: Direct drive | I39: N/A | K39: N/A | L39: 30 | M39: No | N39: Yes | P39: 20 | R39: 1100 | S39: MT830M3
A40: MDF 30-42-12 | B40: Marantec | C40: =D39+0.01 -> 300.01 | D40: 420 | E40: Standard | F40: 12 | G40: 415 | H40: Direct drive | I40: N/A | K40: N/A | L40: 40 | M40: No | N40: Yes | P40: 20 | R40: 1100 | S40: MT842M3
...

Sheet Chaindrive
A1: Motor Description | B1: Manufacturer | C1: Sprocket teeth | D1: Sprocket bore | E1: Plate wheel | F1: Plate bore | G1: Gear ratio | H1: chain size | I1: Motor nm | J1: effective nm | K1: RPM | L1: effective RPM | M1: Voltage | N1: Limit turns | O1: Limit turn ratio adjustement | P1: Sprocket diameter | Q1: Platewheel Diameter | R1: Driveshaft diameter mm | S1: Chain Breaking Strain in newtons | U1: Comments
A4: Ranger 70 1ph 19-57 1/2" | B4: GFA | C4: 19 | D4: 25.4 | E4: 57 | F4: 30 | G4: =E4/C4 -> 3 | H4: 1/2" | I4: 70 | J4: =I4*G4 -> 210 | K4: 32 | L4: =K4/G4 -> 10.666667 | M4: 230 | N4: 40 | O4: =N4/G4 -> 13.333333 | P4: 77.16 | Q4: 230 | R4: 25.4 | S4: 18000
A5: Ranger 70 1ph 15-57 1/2" | B5: GFA | C5: 15 | D5: 25.4 | E5: 57 | F5: 30 | G5: =E5/C5 -> 3.8 | H5: 1/2" | I5: 70 | J5: =I5*G5 -> 266 | K5: 32 | L5: =K5/G5 -> 8.4210526 | M5: 230 | N5: 40 | O5: =N5/G5 -> 10.526316 | P5: 61.09 | Q5: 230 | R5: 25.4 | S5: 18000
A6: Ranger 70 1ph 12-57 1/2" | B6: GFA | C6: 12 | D6: 25.4 | E6: 57 | F6: 30 | G6: =E6/C6 -> 4.75 | H6: 1/2" | I6: 70 | J6: =I6*G6 -> 332.5 | K6: 32 | L6: =K6/G6 -> 6.7368421 | M6: 230 | N6: 40 | O6: =N6/G6 -> 8.4210526 | P6: 61.09 | Q6: 230 | R6: 25.4 | S6: 18000
P7: -
A8: Ranger 90 1ph 19-57 1/2" | B8: GFA | C8: 19 | D8: 25.4 | E8: 57 | F8: 30 | G8: =E8/C8 -> 3 | H8: 1/2" | I8: 90 | J8: =I8*G8 -> 270 | K8: 24 | L8: =K8/G8 -> 8 | M8: 230 | N8: 40 | O8: =N8/G8 -> 13.333333 | P8: 77.16 | Q8: 230 | R8: 25.4 | S8: 18000
A9: Ranger 90 1ph 15-57 1/2" | B9: GFA | C9: 15 | D9: 25.4 | E9: 57 | F9: 30 | G9: =E9/C9 -> 3.8 | H9: 1/2" | I9: 90 | J9: =I9*G9 -> 342 | K9: 24 | L9: =K9/G9 -> 6.3157895 | M9: 230 | N9: 40 | O9: =N9/G9 -> 10.526316 | P9: 61.09 | Q9: 230 | R9: 25.4 | S9: 18000
A10: Ranger 90 1ph 12-57 1/2" | B10: GFA | C10: 12 | D10: 25.4 | E10: 57 | F10: 30 | G10: =E10/C10 -> 4.75 | H10: 1/2" | I10: 90 | J10: =I10*G10 -> 427.5 | K10: 24 | L10: =K10/G10 -> 5.0526316 | M10: 230 | N10: 40 | O10: =N10/G10 -> 8.4210526 | P10: 61.09 | Q10: 230 | R10: 25.4 | S10: 18000
P11: -
A12: Ranger 90 3ph 19-57 1/2" | B12: GFA | C12: 19 | D12: 25.4 | E12: 57 | F12: 30 | G12: =E12/C12 -> 3 | H12: 1/2" | I12: 90 | J12: =I12*G12 -> 270 | K12: 32 | L12: =K12/G12 -> 10.666667 | M12: 415 | N12: 40 | O12: =N12/G12 -> 13.333333 | P12: 77.16 | Q12: 230 | R12: 25.4 | S12: 18000
A13: Ranger 90 3ph 15-57 1/2" | B13: GFA | C13: 15 | D13: 25.4 | E13: 57 | F13: 30 | G13: =E13/C13 -> 3.8 | H13: 1/2" | I13: 90 | J13: =I13*G13 -> 342 | K13: 32 | L13: =K13/G13 -> 8.4210526 | M13: 415 | N13: 40 | O13: =N13/G13 -> 10.526316 | P13: 61.09 | Q13: 230 | R13: 25.4 | S13: 18000
A14: Ranger 90 3ph 12-57 5/8" | B14: GFA | C14: 12 | D14: 25.4 | E14: 57 | F14: 30 | G14: =E14/C14 -> 4.75 | H14: 5/8" | I14: 90 | J14: =I14*G14 -> 427.5 | K14: 32 | L14: =K14/G14 -> 6.7368421 | M14: 415 | N14: 40 | O14: =N14/G14 -> 8.4210526 | P14: 73.6 | Q14: 288 | R14: 25.4 | S14: 22400
P15: -
A16: Ranger150 3ph 18-57 5/8" | B16: GFA | C16: 18 | D16: 25.4 | E16: 57 | F16: 30 | G16: =E16/C16 -> 3.1666667 | H16: 5/8" | I16: 149 | J16: =I16*G16 -> 471.83333 | K16: 48 | L16: =K16/G16 -> 15.157895 | M16: 415 | N16: 40 | O16: =N16/G16 -> 12.631579 | P16: 91.42 | Q16: 288 | R16: 25.4 | S16: 22400
A17: Ranger150 3ph 15-57 5/8" | B17: GFA | C17: 15 | D17: 25.4 | E17: 57 | F17: 30 | G17: =E17/C17 -> 3.8 | H17: 5/8" | I17: 149 | J17: =I17*G17 -> 566.2 | K17: 48 | L17: =K17/G17 -> 12.631579 | M17: 415 | N17: 40 | O17: =N17/G17 -> 10.526316 | P17: 91.42 | Q17: 288 | R17: 25.4 | S17: 22400
A18: Ranger150 3ph 12-57 5/8" | B18: GFA | C18: 12 | D18: 25.4 | E18: 57 | F18: 40 | G18: =E18/C18 -> 4.75 | H18: 5/8" | I18: 150 | J18: =I18*G18 -> 712.5 | K18: 48 | L18: =K18/G18 -> 10.105263 | M18: 415 | N18: 40 | O18: =N18/G18 -> 8.4210526 | P18: 73.6 | Q18: 288 | R18: 25.4 | S18: 22400
P19: -
A20: Ranger220 3ph 15-57 3/4" | B20: GFA | C20: 15 | D20: 30 | E20: 57 | F20: 40 | G20: =E20/C20 -> 3.8 | H20: 3/4" | I20: 220 | J20: =I20*G20 -> 836 | K20: 24 | L20: =K20/G20 -> 6.3157895 | M20: 415 | N20: 40 | O20: =N20/G20 -> 10.526316 | P20: 115.75 | Q20: 345.81 | R20: 25.4 | S20: 22400
P21: -
A23: Ranger 60 Fi 1ph 19-57 1/2" | B23: GFA | C23: 15 | D23: 25.4 | E23: 57 | F23: 30 | G23: =E23/C23 -> 3.8 | H23: 1/2" | I23: 60 | J23: =I23*G23 -> 228 | K23: 80 | L23: =K23/G23 -> 21.052632 | M23: 230 | N23: 40 | O23: =N23/G23 -> 10.526316 | P23: 61.09 | Q23: 230 | R23: 25.4 | S23: 18000
A24: Ranger 90 Fi 1ph 15-57 1/2" | B24: GFA | C24: 15 | D24: 25.4 | E24: 57 | F24: 30 | G24: =E24/C24 -> 3.8 | H24: 1/2" | I24: 90 | J24: =I24*G24 -> 342 | K24: 80 | L24: =K24/G24 -> 21.052632 | M24: 230 | N24: 20 | O24: =N24/G24 -> 5.2631579 | P24: 61.09 | Q24: 230 | R24: 25.4 | S24: 18000
A25: Ranger 90 Fi 3ph 15-57 1/2" | B25: GFA | C25: 15 | D25: 25.4 | E25: 57 | F25: 30 | G25: =E25/C25 -> 3.8 | H25: 1/2" | I25: 90 | J25: =I25*G25 -> 342 | K25: 80 | L25: =K25/G25 -> 21.052632 | M25: 415 | N25: 20 | O25: =N25/G25 -> 5.2631579 | P25: 61.09 | Q25: 230 | R25: 25.4 | S25: 18000
A26: Ranger140 Fi 1ph 18-57 5/8" | B26: GFA | C26: 18 | D26: 25.4 | E26: 57 | F26: 30 | G26: =E26/C26 -> 3.1666667 | H26: 5/8" | I26: 140 | J26: =I26*G26 -> 443.33333 | K26: 80 | L26: =K26/G26 -> 25.263158 | M26: 230 | N26: 20 | O26: =N26/G26 -> 6.3157895 | P26: 91.42 | Q26: 288 | R26: 25.4 | S26: 22400
A27: Ranger140 Fi 3ph 18-57 5/8" | B27: GFA | C27: 18 | D27: 25.4 | E27: 57 | F27: 30 | G27: =E27/C27 -> 3.1666667 | H27: 5/8" | I27: 140 | J27: =I27*G27 -> 443.33333 | K27: 80 | L27: =K27/G27 -> 25.263158 | M27: 415 | N27: 20 | O27: =N27/G27 -> 6.3157895 | P27: 91.42 | Q27: 288 | R27: 25.4 | S27: 22400
A28: Ranger140 fi 1ph 12-57 5/8" | B28: GFA | C28: 12 | D28: 25.4 | E28: 57 | F28: 40 | G28: =E28/C28 -> 4.75 | H28: 5/8" | I28: 140 | J28: =I28*G28 -> 665 | K28: 80 | L28: =K28/G28 -> 16.842105 | M28: 230 | N28: 20 | O28: =N28/G28 -> 4.2105263 | P28: 73.6 | Q28: 288 | R28: 25.4 | S28: 22400
A29: Ranger140 fi 3ph 12-57 5/8" | B29: GFA | C29: 12 | D29: 25.4 | E29: 57 | F29: 40 | G29: =E29/C29 -> 4.75 | H29: 5/8" | I29: 140 | J29: =I29*G29 -> 665 | K29: 80 | L29: =K29/G29 -> 16.842105 | M29: 415 | N29: 20 | O29: =N29/G29 -> 4.2105263 | P29: 73.6 | Q29: 288 | R29: 25.4 | S29: 22400
A32: KE 40.24 15-57 3/4" | B32: GFA | C32: 15 | D32: 40 | E32: 57 | F32: 40 | G32: =E32/C32 -> 3.8 | H32: 3/4" | I32: 400 | J32: =I32*G32 -> 1520 | K32: 24 | L32: =K32/G32 -> 6.3157895 | M32: 415 | N32: 40 | O32: =N32/G32 -> 10.526316 | P32: 192.91 | Q32: 461 | R32: =D32 -> 40 | S32: 60000
A33: KE 40.24 15-57 1" | B33: GFA | C33: 15 | D33: 40 | E33: 57 | F33: 40 | G33: =E33/C33 -> 3.8 | H33: 1" | I33: 400 | J33: =I33*G33 -> 1520 | K33: 24 | L33: =K33/G33 -> 6.3157895 | M33: 415 | N33: 40 | O33: =N33/G33 -> 10.526316 | P33: 192.91 | Q33: 461 | R33: =D33 -> 40 | S33: 60000
A34: KE 60.24 15-57 1" | B34: GFA | C34: 15 | D34: 55 | E34: 57 | F34: 55 | G34: =E34/C34 -> 3.8 | H34: 1" | I34: 600 | J34: =I34*G34 -> 2280 | K34: 24 | L34: =K34/G34 -> 6.3157895 | M34: 415 | N34: 60 | O34: =N34/G34 -> 15.789474 | P34: 192.91 | Q34: 461 | R34: =D34 -> 55 | S34: 60000
A35: KE 80.24 15-57 1" | B35: GFA | C35: 15 | D35: 55 | E35: 57 | F35: 55 | G35: =E35/C35 -> 3.8 | H35: 1" | I35: 800 | J35: =I35*G35 -> 3040 | K35: 24 | L35: =K35/G35 -> 6.3157895 | M35: 415 | N35: 60 | O35: =N35/G35 -> 15.789474 | P35: 152.72 | Q35: 576 | R35: =D35 -> 55 | S35: 95000
A36: KE 80.24 15-57 1 1/4" | B36: GFA | C36: 15 | D36: 55 | E36: 57 | F36: 55 | G36: =E36/C36 -> 3.8 | H36: 1 1/4" | I36: 800 | J36: =I36*G36 -> 3040 | K36: 24 | L36: =K36/G36 -> 6.3157895 | M36: 415 | N36: 60 | O36: =N36/G36 -> 15.789474 | P36: 152.72 | Q36: 576 | R36: =D36 -> 55 | S36: 95000
A39: KE 40.40 Fi 15-57 3/4" | B39: GFA | C39: 15 | D39: 40 | E39: 57 | F39: 40 | G39: =E39/C39 -> 3.8 | H39: 3/4" | I39: 300 | J39: =I39*G39 -> 1140 | K39: 40 | L39: =K39/G39 -> 10.526316 | M39: 230/415 | N39: 40 | O39: =N39/G39 -> 10.526316 | P39: 115.75 | Q39: 345.81 | R39: 40 | S39: 29000
A40: KE 40.40 Fi 15-57 1" | B40: GFA | C40: 15 | D40: 40 | E40: 57 | F40: 40 | G40: =E40/C40 -> 3.8 | H40: 1" | I40: 300 | J40: =I40*G40 -> 1140 | K40: 40 | L40: =K40/G40 -> 10.526316 | M40: 230/415 | N40: 40 | O40: =N40/G40 -> 10.526316 | P40: 115.75 | Q40: 345.81 | R40: 40 | S40: 29000
A41: KE 50.80 Fi 15-57 1" | B41: GFA | C41: 15 | D41: 55 | E41: 57 | F41: 55 | G41: =E41/C41 -> 3.8 | H41: 1" | I41: 500 | J41: =I41*G41 -> 1900 | K41: 80 | L41: =K41/G41 -> 21.052632 | M41: 230/415 | N41: 60 | O41: =N41/G41 -> 15.789474 | P41: 115.75 | Q41: 345.81 | R41: 55 | S41: 60000
A42: KE 80.40 Fi 15-57 1" | B42: GFA | C42: 15 | D42: 55 | E42: 57 | F42: 55 | G42: =E42/C42 -> 3.8 | H42: 1" | I42: 800 | J42: =I42*G42 -> 3040 | K42: 40 | L42: =K42/G42 -> 10.526316 | M42: 230/415 | N42: 60 | O42: =N42/G42 -> 15.789474 | P42: 115.75 | Q42: 345.81 | R42: 55 | S42: 60000
A43: KE 80.40 Fi 15-57 1 1/4" | B43: GFA | C43: 15 | D43: 55 | E43: 57 | F43: 55 | G43: =E43/C43 -> 3.8 | H43: 1 1/4" | I43: 800 | J43: =I43*G43 -> 3040 | K43: 40 | L43: =K43/G43 -> 10.526316 | M43: 230/415 | N43: 60 | O43: =N43/G43 -> 15.789474 | P43: 115.75 | Q43: 345.81 | R43: 55 | S43: 60000
A45: JM200 | B45: Ellard | C45: 11 | D45: 25.4 | E45: 61 | G45: =E45/C45 -> 5.5454545 | H45: 1/2" | I45: 20 | J45: =I45*G45 -> 110.90909 | K45: 34 | L45: =K45/G45 -> 6.1311475 | M45: 415 | R45: 25.4 | S45: 18000
A46: JM500 | B46: Ellard | C46: 9 | E46: 50 | G46: =E46/C46 -> 5.5555556 | H46: 5/8" | I46: 62 | J46: =I46*G46 -> 344.44444 | K46: 34 | L46: =K46/G46 -> 6.12 | M46: 415 | S46: 22400
A47: JM750 | B47: Ellard | C47: 10 | E47: 64 | G47: =E47/C47 -> 6.4 | H47: 5/8" | I47: 95 | J47: =I47*G47 -> 608 | K47: 22 | L47: =K47/G47 -> 3.4375 | M47: 415 | S47: 22400
A48: JM1000 | B48: Ellard | C48: 9 | E48: 57 | G48: =E48/C48 -> 6.3333333 | H48: 3/4" | I48: 128 | J48: =I48*G48 -> 810.66667 | K48: 22 | L48: =K48/G48 -> 3.4736842 | M48: 415 | S48: 29000
...

Sheet Spring data
C1: Lb in/turn | D1: no turns | E1: lift in nm | F1: spring length | G1: lift for door with 2 springs | H1: spring length door
A4: 16\9 | B4: Yellow/Brown | C4: 16 | D4: 9 | E4: =(0.11298*C4)*D4 -> 16.26912 | F4: 406.8 | G4: =E4*2 -> 32.53824 | H4: =F4*2 -> 813.6
A5: 20\9 | B5: Yellow/Silver | C5: 20.49 | D5: 9 | E5: =(0.11298*C5)*D5 -> 20.834642 | F5: 468.2 | G5: =E5*2 -> 41.669284 | H5: =F5*2 -> 936.4
A6: 27\9 | B6: Yellow pink | C6: 20.85 | D6: 9 | E6: =(0.11298*C6)*D6 -> 21.200697 | F6: 543.9 | G6: =E6*2 -> 42.401394 | H6: =F6*2 -> 1087.8
A7: 35\9 | B7: Yellow blue | C7: 34.72 | D7: 9 | E7: =(0.11298*C7)*D7 -> 35.30399 | F7: 648.2 | G7: =E7*2 -> 70.607981 | H7: =F7*2 -> 1296.4
A8: 43\9 | B8: Yellow white | C8: 43 | D8: 9 | E8: =(0.11298*C8)*D8 -> 43.72326 | F8: 774.5 | G8: =E8*2 -> 87.44652 | H8: =F8*2 -> 1549
A9: 56\9 | B9: Yellow orange | C9: 56 | D9: 9 | E9: =(0.11298*C9)*D9 -> 56.94192 | F9: 925.4 | G9: =E9*2 -> 113.88384 | H9: =F9*2 -> 1850.8 | N9: 406.8
A10: 69\9 | B10: Yellow purple | C10: 69.5 | D10: 9 | E10: =(0.11298*C10)*D10 -> 70.66899 | F10: 1104.9 | G10: =E10*2 -> 141.33798 | H10: =F10*2 -> 2209.8 | N10: 468.2
A11: 86\9 | B11: Yellow red | C11: 86 | D11: 9 | E11: =(0.11298*C11)*D11 -> 87.44652 | F11: 1292 | G11: =E11*2 -> 174.89304 | H11: =F11*2 -> 2584 | N11: =N10+N9 -> 875
A12: 104\9 | B12: Yellow | C12: 104 | D12: 9 | E12: =(0.11298*C12)*D12 -> 105.74928 | F12: 1511.5 | G12: =E12*2 -> 211.49856 | H12: =F12*2 -> 3023
A13: 125\9 | B13: Yellow black | C13: 121 | D13: 9 | E13: =(0.11298*C13)*D13 -> 123.03522 | F13: 1729.1 | G13: =E13*2 -> 246.07044 | H13: =F13*2 -> 3458.2

Sheet Chain
A1: Chain Size | B1: Sprocket Size (no. Teeth) | C1: Sprocket Bore size mm | D1: Platewheel Size (no. Teeth) | E1: Platewheel Bore size mm | F1: Chain Breaking Strain | G1: Pitch (mm) | H1: Breaking Strain in n | I1: Ratio | J1: Platewheel diameter
A2: 1/2" | B2: 12 | C2: 25.4 | D2: 57 | E2: 30 | F2: 18000 | G2: =0.5*25.4 -> 12.7 | H2: 18000 | I2: =D2/B2 -> 4.75 | J2: 230.54
A3: 1/2" | B3: 15 | C3: 25.4 | D3: 57 | E3: 30 | F3: 18000 | G3: =0.5*25.4 -> 12.7 | H3: 18000 | I3: =D3/B3 -> 3.8 | J3: 230.54
A4: 1/2" | B4: 19 | C4: 25.4 | D4: 57 | E4: 30 | F4: 18000 | G4: =0.5*25.4 -> 12.7 | H4: 18000 | I4: =D4/B4 -> 3 | J4: 230.54
A5: 5/8" | B5: 12 | C5: 25.4 | D5: 57 | E5: 30/40 | F5: 22400 | G5: =0.625*25.4 -> 15.875 | H5: 22400 | I5: =D5/B5 -> 4.75 | J5: 288.18
A6: 5/8" | B6: 18 | C6: 25.4 | D6: 57 | E6: 30/40 | F6: 22400 | G6: =0.625*25.4 -> 15.875 | H6: 22400 | I6: =D6/B6 -> 3.1666667 | J6: 288.18
A7: 3/4" | B7: 12 | C7: 25.4 | D7: 57 | E7: 40/50 | F7: 29000 | G7: =0.75*25.4 -> 19.05 | H7: 29000 | I7: =D7/B7 -> 4.75 | J7: 345.81
A8: 3/4" | B8: 12 | C8: 30 | D8: 57 | E8: 40/50 | F8: 29000 | G8: =0.75*25.4 -> 19.05 | H8: 29000 | I8: =D8/B8 -> 4.75 | J8: 345.81
A9: 3/4" | B9: 15 | C9: 30 | D9: 57 | E9: 40/50 | F9: 29000 | G9: =0.75*25.4 -> 19.05 | H9: 29000 | I9: =D9/B9 -> 3.8 | J9: 345.81
A10: 1" | B10: 15 | C10: 40 | D10: 57 | E10: 50/60/80 | F10: 60000 | G10: 25.4 | H10: 60000 | I10: =D10/B10 -> 3.8 | J10: 461.07
A11: 1 1/4" | B11: 15 | C11: 55 | D11: 57 | E11: 60/80 | F11: 95000 | G11: =1.25*25.4 -> 31.75 | H11: 95000 | I11: =D11/B11 -> 3.8 | J11: 576.36

Sheet Bearings
A1: Bearing name | B1: Shaft size in mm | C1: newtons | D1: load capacity in kgs | E1: Manufacture | F1: Part No | G1: Bearing image
A2: UCFL206 - 4 hole 30mm | B2: 30 | C2: 5900 | D2: =C2*0.1019716213 -> 601.63257 | E2: Ellard
A3: UCF208 - 4 hole 40mm | B3: 40 | C3: 10800 | D3: =C3*0.1019716213 -> 1101.2935 | E3: Ellard
A4: UCFL206 - 4 hole 30mm | B4: 30 | C4: 11250 | D4: =C4*0.1019716213 -> 1147.1807 | E4: GFA | F4: B/UFC206
A5: UCF208 - 4 hole 40mm | B5: 40 | C5: 18100 | D5: =C5*0.1019716213 -> 1845.6863 | E5: GFA | F5: B/UFC208
A6: UCF211- 4 hole 55mm | B6: 55 | C6: 29200 | D6: =C6*0.1019716213 -> 2977.5713 | E6: GFA | F6: B/UFC211
A7: UCF212 - 4 hole 60mm | B7: 60 | C7: 32800 | D7: =C7*0.1019716213 -> 3344.6692 | E7: GFA | F7: B/UFC212
B8: 80 | E8: Other

Sheet SafetyB
A1: Name | B1: Operating Torque (Nm) | C1: Max Safety Torque (Nm) | D1: Max Locking Speed (RPM) | E1: Manufacture | F1: Door max weight in kgs on 100mm axle | G1: Driveshaft diameter mm | H1: Stop distance | I1: SB image | J1: SWS stock code | K1: Notes
A2: RD80 | B2: 95 | C2: 545 | D2: 22 | E2: Timmer | F2: 150 | G2: 18s | H2: 10
A3: RD150 | B3: 147 | C3: 812 | D3: 22 | E3: Timmer | F3: 200 | G3: 18s | H3: 10
A4: TA 1/2 RD | B4: 332 | C4: 796 | D4: 22 | E4: Timmer | F4: 460 | G4: 30 | H4: 10
A5: TA 2/3 RD | B5: 552 | C5: 1253 | D5: 22 | E5: Timmer | G5: 40 | H5: 10
A6: FG 80 -40 | B6: 800 | C6: 2330 | D6: 24 | E6: GFA | G6: 40 | H6: 10
A7: FG 120 -50 | B7: 1200 | C7: 3530 | D7: 24 | E7: GFA | G7: 50 | H7: 10
A8: FG 220 -60 | B8: 2200 | C8: 6691 | D8: 15 | E8: GFA | G8: 60 | H8: 10 | K8: shaft type? Keyed type 2? What is that?
A9: FG 360 - 80 | B9: 3600 | C9: 10260 | D9: 15 | E9: GFA | G9: 80 | H9: 10 | K9: Out side our current scope required.
O10: RSB-G | P10: 130 | Q10: 276 | R10: 22 | S10: Ellard | U10: 18s | V10: 10
O11: GDB 18 | P11: 145 | Q11: 365 | R11: 22 | S11: Ellard | T11: 200 | U11: 18s | V11: 10
O12: RSB 1 / 2 (RSB1-30) | P12: 332 | Q12: 1444 | R12: 22 | S12: Ellard | T12: 460 | U12: 30 | V12: 10
O13: RSB 2 / 3 (RSB1-40) | P13: 542 | Q13: 1863 | R13: 22 | S13: Ellard | U13: 40 | V13: 10
O14: RSB 4 (PCM10A) | P14: 1000 | Q14: 3560 | R14: 12 | S14: Ellard | U14: 50 | V14: 10

Sheet Endplate
A1: Name | B1: Size | C1: Max load kgs | D1: Material | E1: Thickness mm | F1: Fixing holes | G1: Offset | H1: Group name | J1: 75mm | K1: 77mm | L1: 95mm | M1: 100mm | N1: cd150 | O1: cd38 | P1: cd60 | Q1: cd80 | R1: cd90 | S1: cd300 | T1: cd77
A3: EVO 300 (40) | B3: 300 | C3: 500 | D3: Steel | E3: 3 | F3: =B3-50 -> 250 | G3: 40 | H3: Traditional with motor
A4: EVO 350 (40) | B4: 350 | C4: 450 | D4: Steel | E4: 3 | F4: =B4-50 -> 300 | G4: 40 | H4: Traditional with motor
A5: EVO 400 (40) | B5: 400 | C5: 550 | D5: Steel | E5: 4 | F5: =B5-50 -> 350 | G5: 40 | H5: Traditional with motor
A6: EVO 450 (40) | B6: 450 | C6: 550 | D6: Steel | E6: 4 | F6: =B6-50 -> 400 | G6: 40 | H6: Traditional with motor
A7: EVO 300 (60) | B7: 300 | C7: 500 | D7: Steel | E7: 3 | F7: =B7-50 -> 250 | G7: 60 | H7: Traditional with motor
A8: EVO 350 (60) | B8: 350 | C8: 450 | D8: Steel | E8: 3 | F8: =B8-50 -> 300 | G8: 60 | H8: Traditional with motor
A9: EVO 400 (60) | B9: 400 | C9: 550 | D9: Steel | E9: 4 | F9: =B9-50 -> 350 | G9: 60 | H9: Traditional with motor
A10: EVO 450 (60) | B10: 450 | C10: 550 | D10: Steel | E10: 4 | F10: =B10-50 -> 400 | G10: 60 | H10: Traditional with motor
A12: Industrial 300 | B12: 300 | C12: 700 | D12: Steel | E12: 6 | F12: =B12-50 -> 250 | G12: 92 | H12: Industrial with motor
A13: Industrial 350 | B13: 350 | C13: 650 | D13: Steel | E13: 6 | F13: =B13-50 -> 300 | G13: 92 | H13: Industrial with motor
A14: Industrial 400 | B14: 400 | C14: 1200 | D14: Steel | E14: 8 | F14: =B14-50 -> 350 | G14: 92 | H14: Industrial with motor
A15: Industrial 450 | B15: 450 | C15: 1100 | D15: Steel | E15: 8 | F15: =B15-50 -> 400 | G15: 92 | H15: Industrial with motor
... A40: Industrial 600 flat | B40: 600 | C40: 2200 | D40: Steel | E40: 10 | F40: =B40-50 -> 550 | G40: 10 | H40: Industrial with motor

Sheet Wicket doors
A1: Name | B1: Height | C1: Width
A2: Standard | B2: 1650 | C2: 550
A3: Euro door | B3: 1875 | C3: 750

Sheet Wind class
A3: Lath | B3: Manufacturer | C3: Guide | D3: Width | E3: Angle thickness | F3: Class
A6: 75mm 22g | B6: CRF | C6: 65 | D6: 4000 | E6: 3 | F6: 5
A7: 75mm 22g | B7: CRF | C7: 65 wind | D7: 5000 | E7: ? | F7: 5
A8: 75mm 22g perf | B8: CRF | C8: 65 | D8: 4000 | E8: 3 | F8: 5
A9: 75mm 20g | B9: CRF | C9: 65 wind | D9: 6000 | E9: ? | F9: 5
A10: 75mm 20g | B10: CRF | C10: 65 wind | D10: 8000 | E10: 6 | F10: 5
A11: 75mm 20g | B11: CRF | C11: 65 wind | D11: 10000 | E11: 6 | F11: 3
A13: 75mm 18g | B13: CRF | C13: 100 wind | D13: 10000 | E13: 6 | F13: 5
A14: 75mm 18g | B14: CRF | C14: 100 wind | D14: 12000 | E14: 6 | F14: 3
A17: 100mm | B17: CRF | C17: 90mm | D17: 10000 | E17: 6 | F17: 5
A19: 75mm 22g | B19: West Mercia | C19: 65 | D19: 4600 | E19: 3 | F19: 2
A20: 75mm 22g | B20: West Mercia | C20: 65 wind | D20: 6100 | E20: 3 | F20: 5
A21: 75mm 20g | B21: West Mercia | C21: 100 wind | D21: 8000 | E21: 5 | F21: 5

Sheet Size range
A2: Sizes to be confimed, this is to test logic.
A4: Clear opening | B4: operation | C4: Min width | D4: Max width | E4: Min height | F4: Max height
A5: 75mm 22g | B5: Tube motor | C5: 1000 | D5: 6000 | E5: 500 | F5: 6000
A6: 75mm 20g | B6: Tube motor | C6: 1000 | D6: 8200 | E6: 500 | F6: 8000
A7: 75mm 18g | B7: Tube motor | C7: 1000 | D7: 9000 | E7: 500 | F7: 8000
A8: 95mm | B8: Tube motor | C8: 1000 | D8: 9000 | E8: 500 | F8: 8000
A9: 100mm | B9: Tube motor | C9: 1000 | D9: 9000 | E9: 500 | F9: 8000
A11: 75mm 22g | B11: Industrial motor | C11: 1000 | D11: 6000 | E11: 500 | F11: 6000
A12: 75mm 20g | B12: Industrial motor | C12: 1000 | D12: 8200 | E12: 500 | F12: 8000
A13: 75mm 18g | B13: Industrial motor | C13: 1000 | D13: 9000 | E13: 500 | F13: 8000
A14: 95mm | B14: Industrial motor | C14: 1000 | D14: 9000 | E14: 500 | F14: 8000
A15: 100mm | B15: Industrial motor | C15: 1000 | D15: 9000 | E15: 500 | F15: 8000
A17: 75mm 22g | B17: Spring | C17: 1000 | D17: 6000 | E17: 500 | F17: 3000
A18: 75mm 20g | B18: Spring | C18: 1000 | D18: 4000 | E18: 500 | F18: 3000
... A21: 100mm | B21: Spring | C21: 1000 | D21: 2000 | E21: 500 | F21: 3000
A23: 75mm 22g | B23: Chain
A24: 75mm 20g | B24: Chain
A25: 75mm 18g | B25: Chain
A26: 95mm | B26: Chain
A27: 100mm | B27: Chain

Sheet Online codes
A1: CODE | B1: Description | D1: Lath type | E1: Guide type | F1: Endlock type | G1: Reveal offsets | H1: Product class
A2: Y752 | B2: SeceuroDoor 75 22g - Industrial Motor Shutter | C2: 1 | H2: GAEC | K2: G=Guide
A3: Y750 | B3: SeceuroDoor 75 20g - Industrial Motor Shutter | C3: 2 | H3: GAEC | K3: B=boxsection
A4: Y077 | B4: SeceuroDoor 77 - Insulated Industrial Motor Shutter | C4: 3 | H4: GAEC | K4: EF = flat endplate
A5: Y100 | B5: SeceuroDoor 100 - Insulated Industrial Motor Shutter | C5: 5 | H5: GAEC | K5: EC = cranked endplate
A6: Y752 | B6: SeceuroDoor 75c 22g - Industrial Hand Chain Shutter | C6: 6 | K6: A = Angle
A7: Y750 | B7: SeceuroDoor 75c 20g - Industrial Hand Chain Shutter | C7: 7 | K7: RA = reveal angle
A8: Y077 | B8: SeceuroDoor 77c - Insulated Industrial Hand Chain Shutter | C8: 8
A9: YC752SM | B9: SeceuroDoor Continental 75 22g - Tube Motor Shutter | C9: 9
A10: YC752PM | B10: SeceuroDoor Continental 75 22g - Tube Motor, Full Vision Shutter | C10: 10
A11: YC750SM | B11: SeceuroDoor Continental 75 20g - Tube Motor Shutter | C11: 11
A12: YC750PM | B12: SeceuroDoor Continental 75 20g - Tube Motor Full Vision Shutter | C12: 12
A13: YT077SM | B13: SeceuroDoor Traditional 77t - Insulated Tube Motor Shutter | C13: 13
A14: YT752SM | B14: SeceuroDoor Traditional 75 22g - Tube Motor Shutter | C14: 14
A15: YT752PM | B15: SeceuroDoor Traditional 75 22g - Tube Motor Full Vision Shutter | C15: 15
A16: YT750SM | B16: SeceuroDoor Traditional 75 20g - Tube Motor Shutter | C16: 16
A17: YT750PM | B17: SeceuroDoor Traditional 75 20g - Tube Motor Full Vision Shutter | C17: 17
A18: YT8750 | B18: SeceuroDoor Traditional Plus 75 20g - Tube Motor Shutter | C18: 18
A19: YCOS | B19: SeceuroDoor Continental 75 22g - Spring Operated Shutter | C19: 19
... A36: YT750SME | B36: SeceuroDoor Traditional (EVO) 75 20g - Tube Motor Shutter | C36: 416
